Workbook

Sheet README
A1: MSCAST ERP – Requirements Traceability Workbook
A2: Version 2.0 · 21 September 2026 · matches doc 03 (Requirements Traceability) v3.0
A4: What this workbook answers
A5: 1. Did the system cover everything MSCAST asked for? → sheet "From MSCAST requirements": the 97 requirements in MSCAST's document ERP_Requirement_Final.pdf, how each is met, and where to see it working.
A6: 2. What was added beyond the requirement document to make it a working, safe system for MSCAST? → sheet "Added to make it work": each addition, in plain words, with the requirement it protects.
A7: 3. What does MSCAST (or the CA) still have to answer? → sheet "Open Questions". Yellow cells are for the answer.
A8: Totals for all three are on the "Summary" sheet and recalculate from the other sheets.
A10: The two systems
A11: Live POC: https://mscast.carobar.net – MSCAST staff are trying it with their own logins.
A12: DEV: https://mscastdev.carobar.net – full demonstration data; the "Evidence" column refers to documents you can open there.
A14: Column legend (From MSCAST requirements)
A15: Type: Standard = ERPNext out of the box · Config = settings, roles, print formats, alerts · Custom = new forms, reports or rules built for MSCAST · Integration = connects an outside device · External = done outside the ERP (CA, policy).
... A18: "In ERPens proposal" is the implementer's reading of the ERPens scope document, not confirmed by ERPens.

Sheet Summary
A1: Summary
A3: Where the system comes from
A4: Basis | B4: Items | C4: Share
A5: From MSCAST requirements | B5: =COUNTA('From MSCAST requirements'!A2:A500) -> 97 | C5: =IF($B$7=0,0,B5/$B$7) -> 0.80833333
A6: Added to make it work | B6: =COUNTA('Added to make it work'!A2:A500) -> 23 | C6: =IF($B$7=0,0,B6/$B$7) -> 0.19166667
A7: Total | B7: =B5+B6 -> 120
A9: MSCAST requirements by status
A10: Status | B10: Count
A11: Working | B11: =COUNTIF('From MSCAST requirements'!J2:J500,A11) -> 91
A12: Working – assumption to confirm | B12: =COUNTIF('From MSCAST requirements'!J2:J500,A12) -> 6
A13: Not working | B13: =COUNTIF('From MSCAST requirements'!J2:J500,A13) -> 0
A14: Changed by MSCAST | B14: =COUNTIF('From MSCAST requirements'!J2:J500,A14) -> 0
A15: Total | B15: =SUM(B11:B14) -> 97
A17: MSCAST requirements by type
A18: Type | B18: Count
A19: Standard | B19: =COUNTIF('From MSCAST requirements'!G2:G500,A19) -> 48
A20: Config | B20: =COUNTIF('From MSCAST requirements'!G2:G500,A20) -> 23
A21: Custom | B21: =COUNTIF('From MSCAST requirements'!G2:G500,A21) -> 22
A22: Integration | B22: =COUNTIF('From MSCAST requirements'!G2:G500,A22) -> 1
A23: External | B23: =COUNTIF('From MSCAST requirements'!G2:G500,A23) -> 1
A24: Open question | B24: =COUNTIF('From MSCAST requirements'!G2:G500,A24) -> 2
A25: Total | B25: =SUM(B19:B24) -> 97
A27: MSCAST requirements by area
A28: Area | B28: Count
A29: Sales | B29: =COUNTIF('From MSCAST requirements'!B2:B500,A29) -> 5
A30: Projects | B30: =COUNTIF('From MSCAST requirements'!B2:B500,A30) -> 9
A31: Project coordination | B31: =COUNTIF('From MSCAST requirements'!B2:B500,A31) -> 19
A32: Engineering | B32: =COUNTIF('From MSCAST requirements'!B2:B500,A32) -> 6
A33: Procurement | B33: =COUNTIF('From MSCAST requirements'!B2:B500,A33) -> 13
A34: Erection & Commissioning | B34: =COUNTIF('From MSCAST requirements'!B2:B500,A34) -> 1
A35: Operations flow | B35: =COUNTIF('From MSCAST requirements'!B2:B500,A35) -> 1
A36: Accounts | B36: =COUNTIF('From MSCAST requirements'!B2:B500,A36) -> 14
A37: Management modules | B37: =COUNTIF('From MSCAST requirements'!B2:B500,A37) -> 4
A38: Accounts POV (compliance) | B38: =COUNTIF('From MSCAST requirements'!B2:B500,A38) -> 2
A39: Accounts POV (controls) | B39: =COUNTIF('From MSCAST requirements'!B2:B500,A39) -> 3
A40: Accounts POV (Companies Act s.128) | B40: =COUNTIF('From MSCAST requirements'!B2:B500,A40) -> 1
A41: Accounts POV (standards) | B41: =COUNTIF('From MSCAST requirements'!B2:B500,A41) -> 1
A42: Accounts POV (equity & liabilities) | B42: =COUNTIF('From MSCAST requirements'!B2:B500,A42) -> 4
A43: Accounts POV (assets) | B43: =COUNTIF('From MSCAST requirements'!B2:B500,A43) -> 4
A44: Accounts POV (inventory) | B44: =COUNTIF('From MSCAST requirements'!B2:B500,A44) -> 3
...

Sheet From MSCAST requirements
A1: ID | B1: Area | C1: Requirement (MSCAST document) | D1: Source page | E1: How the system meets it | F1: Type (detail) | G1: Type | H1: Phase | I1: Size | J1: Status | K1: Evidence on DEV (open these) | L1: Assumption to confirm (who) | M1: Open question | N1: In ERPens proposal | O1: Basis
A2: S-01 | B2: Sales | C2: Prepare Sales Orders from customer orders | D2: p2 | E2: ERPNext Sales Order (customer PO no./date, payment terms template) | F2: Standard | G2: Standard | H2: P1 | I2: S | J2: Working | K2: 3 sales orders submitted with customer PO no., retention/LD/PBG fields | N2: Yes | O2: MSCAST requirement
A3: S-02 | B3: Sales | C3: PCC sheet (Purchase Cost Calculation): cost price of each component of CCM/spares, prepared by Sales from the Sales Order | D3: p2, p6 | E3: Custom 'PCC' doctype linked to Sales Order/Project: component lines, revisions + approval; baseline for PO control and project MIS | F3: Custom (no-code + script report) | G3: Custom | H3: P1 | I3: L | J3: Working | K3: PCC-2026-00001 (R2, approved, 15 lines, Rs 1.82 Cr) and PCC-2026-00002 (approved). A director approves. A director may also prepare one (T6e, Q20) | M3: Q2, Q20 | N3: No | O3: MSCAST requirement
A4: S-03 | B4: Sales | C4: Order-status analysis; leads from customer enquiry or direct approach | D4: p2 | E4: CRM Lead → Opportunity → Quotation; Sales Pipeline Analytics | F4: Standard | G4: Standard | H4: P1 | I4: S | J4: Working | K4: Lead (Gulf Aluminium), 2 Opportunities, Quotation SAL-QTN-2026-00001; order-book chart. Plus 14 bid outcomes (6 won / 6 lost with reasons) | N4: Yes | O4: MSCAST requirement
A5: S-04 | B5: Sales | C5: Scope of work/contract and PCC handed to Engineering and Projects | D5: p2, p6 | E5: Kick-off workflow on Project; mandatory attachments and notifications | F5: Config | G5: Config | H5: P1 | I5: S | J5: Working | K5: MSCAST Project Kickoff form with the 8-point customer-PO checklist, linked PCC / SO / project. Kick-off approval is a director's | N5: Partly | O5: MSCAST requirement
A6: S-05 | B6: Sales | C6: List of potential/probable customers for forecasting | D6: p2 | E6: Leads/Opportunities with expected value and closing date | F6: Standard | G6: Standard | H6: P1 | I6: S | J6: Working | K6: Open lead + spares opportunity; 'Order Book by Customer' chart | N6: Yes | O6: MSCAST requirement
A7: PR-01 | B7: Projects | C7: Internal kick-off meeting; Projects receives PCC, signed tech specs, sales MOMs | D7: p2 | E7: Project Template + kick-off checklist child table; Workflow 'Kick-off done' | F7: Config | G7: Config | H7: P1 | I7: S | J7: Working | K7: Project kick-off task completed on PROJ-0001, PCC + SO linked | N7: Yes | O7: MSCAST requirement
A8: PR-02 | B8: Projects | C8: Project planning: targets for Engineering, Procurement, Despatch, Erection & Commissioning | D8: p2 | E8: Project tasks, milestones, dependencies, Gantt | F8: Standard | G8: Standard | H8: P1 | I8: S | J8: Working | K8: Tasks across 3 projects with dates, status and progress | N8: Yes | O8: MSCAST requirement
A9: PR-03 | B9: Projects | C9: Prepare and submit Project Execution, Delivery and Billing schedules to client/consultant | D9: p2, p6 | E9: Delivery + billing schedule child tables on Project/SO; print formats | F9: Config + light custom | G9: Config | H9: P1/P3 | I9: M | J9: Working | K9: 'MSCAST Project Schedule (Client)' print - contractual milestones with live drawing, inspection, dispatch and commissioning status | N9: Partly | O9: MSCAST requirement
A10: PR-04 | B10: Projects | C10: Periodic 'Overall Project Status/Schedule' submission to client | D10: p2 | E10: Project status print format/report | F10: Custom (report + print) | G10: Custom | H10: P1 | I10: M | J10: Working | K10: 'MSCAST Project Status Report' - progress bar, commercial and engineering position, open punch points | N10: No | O10: MSCAST requirement
A11: PR-05 | B11: Projects | C11: Submit invoices and follow up receivables from client | D11: p2 | E11: Accounts Receivable, Payment Reminder/Dunning, Notification before due date | F11: Standard | G11: Standard | H11: P4 | I11: S | J11: Working | K11: Payment request + AR ageing + overdue notification | N11: Yes | O11: MSCAST requirement
A12: PR-06 | B12: Projects | C12: Project completion: completeness of supplies | D12: p3 | E12: Sales Order Analysis (ordered vs delivered), SO–DN tracking | F12: Standard | G12: Standard | H12: P3 | I12: S | J12: Working | K12: MSCAST Dispatch Schedule shows ordered vs delivered vs pending | N12: Partly | O12: MSCAST requirement
A13: PR-07 | B13: Projects | C13: Additional claims discussion and settlement with client | D13: p3 | E13: Custom 'Client Claim' doctype → amended SO / additional invoice | F13: Custom (no-code) | G13: Custom | H13: P3 | I13: S | J13: Working | K13: Client Claim register + print; CLM-2026-00001 (Rs 6.85 L scope variation, agreed Rs 6.40 L) and CLM-2026-00002 (idle time, settled by supplementary invoice) | M13: Q14 | N13: No | O13: MSCAST requirement
A14: PR-08 | B14: Projects | C14: Obtain Commissioning, Preliminary and Final certificates from client | D14: p3, p6 | E14: Custom 'Project Certificate' doctype; triggers milestone billing and retention clock | F14: Custom (no-code) | G14: Custom | H14: P3 | I14: S | J14: Working | K14: Certificates across projects with retention due date + print format | N14: Yes (completion certificate) | O14: MSCAST requirement
A15: PR-09 | B15: Projects | C15: After final closure, hand over project info to Spares Dept for spares business | D15: p3 | E15: Project closure checklist; installed-machine record + customer spares price list | F15: Config | G15: Config | H15: P5 | I15: S | J15: Working | K15: MSCAST Spares Handover + print. Plus the MSCAST Installed Machine register: 14 machines, 2009–2024, the basis of the spares and retrofit business | M15: Q15 | N15: No | O15: MSCAST requirement
A16: PC-01 | B16: Project coordination | C16: Check customer PO against agreed terms; forward to Finance and Procurement | D16: p3, p6 | E16: SO approval workflow with PO-vs-quotation check; notifications | F16: Config | G16: Config | H16: P1 | I16: S | J16: Working | K16: 'MSCAST Project Kick-off' workflow: Draft → PO Verified (Accounts, only when price, scope, payment terms and GST are ticked) → Kick-off Approved (director); PROJ-0002 sits in 'PO Query Raised' because the customer's payment terms differ from the offer | M16: Q20 | N16: Partly | O16: MSCAST requirement
A17: PC-02 | B17: Project coordination | C17: Give billing and dispatch schedule to Procurement based on PCC | D17: p3, p6 | E17: Schedule child tables visible in Procurement workspace; report | F17: Config | G17: Config | H17: P2 | I17: S | J17: Working | K17: 'Billing / Dispatch Schedule' child table on the Project + report, carrying the action note per milestone | N17: Partly | O17: MSCAST requirement
A18: PC-03 | B18: Project coordination | C18: Check supplier POs against PCC requirement and commercial terms | D18: p3, p6 | E18: Validation + 'PO vs PCC' variance report; approval required if over PCC | F18: Custom (script report + server script) | G18: Custom | H18: P2 | I18: M | J18: Working | K18: MSCAST PO vs PCC Variance report + PO PCC fields + 'PO over PCC' notification | M18: Q2 | N18: No | O18: MSCAST requirement
A19: PC-04 | B19: Project coordination | C19: Issue Delivery Instruction to supplier for dispatch to customer site | D19: p3, p4, p6 | E19: Custom 'Delivery Instruction' doctype from PO/MDM | F19: Custom (no-code) | G19: Custom | H19: P3 | I19: M | J19: Working | K19: DI-2026-00001 with consignee, transporter, LR, vehicle + print format | M19: Q5 | N19: Yes | O19: MSCAST requirement
A20: PC-05 | B20: Project coordination | C20: Free-issue list dispatched with Delivery Instruction to sub-contractor | D20: p3 | E20: Subcontracting supplied items / Stock Entry; Annexure-I print | F20: Standard + print format | G20: Standard | H20: P2/P3 | I20: S | J20: Working | K20: Free-issue stock transfer to 'Free Issue at Vendor' + Annexure-I on the DI print | N20: Yes | O20: MSCAST requirement
A21: PC-06 | B21: Project coordination | C21: Receive purchase bills, check against PO and Delivery Instruction; original to Accounts, duplicate to Purchase for BRM | D21: p3 | E21: BRM register records supplier bill against PO; Purchase Invoice with certification workflow | F21: Custom → Standard + workflow | G21: Custom | H21: P2/P4 | I21: M | J21: Working | K21: 3 BRMs against POs. Workflow: Purchase prepares → a director certifies → Accounts marks paid. A director can also do all three steps alone (T6g, Q21) | M21: Q21 | N21: No | O21: MSCAST requirement
A22: PC-07 | B22: Project coordination | C22: Prepare Sales Invoice, Delivery Challan and Packing List | D22: p3, p7 | E22: Delivery Note, Packing Slip, Sales Invoice; e-way bill | F22: Standard | G22: Standard | H22: P3/P4 | I22: S | J22: Working | K22: 6 sales invoices, 3 delivery notes; packing slip not demoed | N22: Yes | O22: MSCAST requirement
A23: PC-08 | B23: Project coordination | C23: Update stock items and free-issue statement | D23: p3 | E23: Stock Ledger; vendor-wise free-issue balance report | F23: Standard + report | G23: Standard | H23: P2 | I23: S | J23: Working | K23: MSCAST Free Issue at Vendor report (plate + sections at vendor) | N23: Yes | O23: MSCAST requirement
A24: PC-09 | B24: Project coordination | C24: Update billing & despatch schedule with consignor, transporter, LR no./date, invoice no./date | D24: p3 | E24: Delivery Note transporter/LR/vehicle fields + schedule-vs-actual report | F24: Standard + report | G24: Standard | H24: P3 | I24: S | J24: Working | K24: DN carries transporter, LR no./date, vehicle; dispatch schedule report | N24: Partly | O24: MSCAST requirement
A25: PC-10 | B25: Project coordination | C25: Project code allocation | D25: p3 | E25: Project naming series | F25: Config | G25: Config | H25: P0 | I25: S | J25: Working | K25: PROJ-0001 / 0002 / 0003 | N25: Yes | O25: MSCAST requirement
A26: PC-11 | B26: Project coordination | C26: Update ongoing/new and executed/closed project and Sales Order lists | D26: p3 | E26: Project and Sales Order list views/reports with status filters | F26: Standard | G26: Standard | H26: P1 | I26: S | J26: Working | K26: List views with status filters | N26: Yes | O26: MSCAST requirement
A27: PC-12 | B27: Project coordination | C27: Maintain supplier and customer information | D27: p3 | E27: Customer/Supplier masters (GSTIN, PAN, MSME/Udyam, contacts, addresses) | F27: Standard + custom fields | G27: Standard | H27: P0/P1 | I27: S | J27: Working | K27: 13 customers, 15 suppliers with GSTIN, state, MSME type and addresses. GSTIN check digits and pincode-to-state validated on entry | N27: Yes | O27: MSCAST requirement
A28: PC-13 | B28: Project coordination | C28: New Project MIS as per given template | D28: p3 | E28: Custom project MIS report per MSCAST template | F28: Custom (script report) | G28: Custom | H28: P1/P4 | I28: M | J28: Working | K28: MSCAST Project MIS report (contract vs PCC vs PO vs billed vs hours) | M28: Q3 | N28: No | O28: MSCAST requirement
A29: PC-14 | B29: Project coordination | C29: Project completion accounting closure reports | D29: p3 | E29: Project Profitability + custom closure report | F29: Custom (script report) | G29: Custom | H29: P4 | I29: M | J29: Working | K29: 'MSCAST Project Closure Report' with a closure verdict per project | N29: No | O29: MSCAST requirement
A30: PC-15 | B30: Project coordination | C30: Pending Sales Order review | D30: p3 | E30: Sales Order Analysis / pending items to deliver and bill | F30: Standard | G30: Standard | H30: P1 | I30: S | J30: Working | K30: Pending quantities in the dispatch schedule report | N30: Yes | O30: MSCAST requirement
A31: PC-16 | B31: Project coordination | C31: Material movement tracking | D31: p3 | E31: Stock Ledger, Project-wise Stock Tracking, DI/Delivery Note status | F31: Standard + report | G31: Standard | H31: P2/P3 | I31: S | J31: Working | K31: Stock ledger, project-wise stock, stock entries, DI/DN status | N31: Partly | O31: MSCAST requirement
A32: PC-17 | B32: Project coordination | C32: Proforma Invoice for advance/scheduled supply per SO payment terms | D32: p3 | E32: 'Proforma Invoice' print format on Sales Order + Payment Request | F32: Config (print format) | G32: Config | H32: P3 | I32: S | J32: Working | K32: 'MSCAST Proforma Invoice' + advance payment request | N32: No | O32: MSCAST requirement
A33: PC-18 | B33: Project coordination | C33: Supplementary Invoice for retention amount | D33: p3 | E33: Payment Terms Template + retention tracker; Retention Receivable account | F33: Custom | G33: Custom | H33: P3/P4 | I33: M | J33: Working | K33: Retention reclassified to Retention Receivable on two projects; supplementary invoice against the agreed claim | N33: Yes (retention tracking) | O33: MSCAST requirement
A34: PC-19 | B34: Project coordination | C34: Track Sales Order vs Purchase Order vs Supply Invoice | D34: p3 | E34: Custom tracker report SO ↔ PCC ↔ PO ↔ PI ↔ SI | F34: Custom (script report) | G34: Custom | H34: P3/P4 | I34: M | J34: Working | K34: 'MSCAST SO - PO - Invoice Tracker' per order | N34: No | O34: MSCAST requirement
A35: E-01 | B35: Engineering | C35: Receive PCC / division scope list | D35: p4 | E35: Link on Project; notification | F35: Config | G35: Config | H35: P1 | I35: S | J35: Working | K35: PCC linked from the project; engineering tasks assigned | N35: Partly | O35: MSCAST requirement
A36: E-02 | B36: Engineering | C36: Prepare engineering programme and design/drawings | D36: p4, p6 | E36: Engineering tasks + Drawing Register (revisions, approvals, transmittals, Drive links) | F36: Custom (no-code + workflow) | G36: Custom | H36: P1 | I36: L | J36: Working | K36: 9 drawings with revision tables and Drive links; MSCAST Drawing Register report. 'MSCAST Drawing Release' workflow: Draft → For Customer Approval → Approved by Customer → Released for Manufacture → Superseded. Only a Projects Manager releases, and only from *Approved by Customer* | N36: Yes | O36: MSCAST requirement
A37: E-03 | B37: Engineering | C37: Prepare MDF once drawings are final | D37: p4, p6 | E37: Engineering BOM or custom 'MDF' doctype with print; generates Material Requests | F37: Config + custom print | G37: Config | H37: P1 | I37: M | J37: Working | K37: 3 MDFs (WSU, Mould, Hydraulics) + MDF print format | N37: Yes | O37: MSCAST requirement
A38: E-04 | B38: Engineering | C38: Finalise extra bought-out item list | D38: p4, p6 | E38: Bought-out item groups; Material Request from BOM/MDF | F38: Standard | G38: Standard | H38: P1/P2 | I38: S | J38: Working | K38: Bought-out item groups; Material Request raised from the MDF lists | M38: Q18 | N38: Yes | O38: MSCAST requirement
A39: E-05 | B39: Engineering | C39: Send MDF and bought-out list to Procurement; follow up | D39: p4 | E39: MDF submit → Material Request + notification; Procurement Tracker report | F39: Config | G39: Config | H39: P2 | I39: S | J39: Working | K39: MSCAST Transmittal register + note print; drawing set issued to the customer (acknowledged) and to the fabricator | N39: Yes | O39: MSCAST requirement
A40: E-06 | B40: Engineering | C40: Capture engineering man-hours equipment-wise and project-wise | D40: p8 | E40: Timesheet with custom 'Equipment' field + man-hour report | F40: Config + custom field/report | G40: Config | H40: P1 | I40: S | J40: Working | K40: Timesheets with Equipment field; 'Engineering Hours by Activity' chart. The overnight sweep flags any open project with no time ever booked | M40: Q17 | N40: Yes (manhours) | O40: MSCAST requirement
...

Sheet Added to make it work
A1: ID | B1: Kind | C1: What was added | D1: Why MSCAST needs it (plain words) | E1: Protects requirement(s) | F1: Where to see it | G1: Automatic check (technical) | H1: Basis
A2: X-01 | B2: Reliability | C2: Installable application package (mscast_erp) | D2: The same system can be installed on MSCAST's own server and upgraded safely. Nothing lives only on the builder's laptop. | E2: All; AC-06 | F2: Repository github.com/cb1-tech/mscast | G2: T6m | H2: Added by the implementer
A3: X-02 | B3: Reliability | C3: One-step fresh install that tests itself | D3: A clean production system can be built in one step, and it refuses to report success unless 19 system checks pass. | E3: AC-06 | F3: Script new-mscast-site.sh; doc 08 | G3: T1–T7b (system set) | H3: Added by the implementer
A4: X-03 | B4: Reliability | C4: Nightly backup, with restore tested | D4: Data can be recovered after a failure. The books must stay recoverable (Companies (Accounts) Rules r.3(5)). The backup carries the encryption key so saved passwords still work after a restore. | E4: AC-06 | F4: Windows task "MSCAST nightly backup" 02:30 JST; restore-test.sh | G4: T9g, T9h | H4: Added by the implementer
A5: X-04 | B5: Reliability | C5: Backup watchdog and failure alerts | D5: Someone is emailed if the nightly backup or the checks fail, or if the nightly job stops running. | E5: AC-06 | F5: Email to the implementer; 09:00 IST watchdog | G5: T9h | H5: Added by the implementer
A6: X-05 | B6: Reliability | C6: 42 automatic checks, run every night | D6: The system tests itself: reports run, prints render, the books balance, controls hold, permissions are right. Problems are caught before staff meet them. | E6: AC-01, AC-03 | F6: POC README, section "Build checks" | G6: all | H6: Added by the implementer
A7: X-06 | B7: Safeguard | C7: Payment block on every way of paying a supplier | D7: Money cannot go out on a supplier bill without a certified BRM – whether paid by Payment Entry, Journal Entry or as an advance, and not above the certified amount. Utilities, rent and statutory payees are marked exempt so they can still be paid. | E7: P-08, A-05, A-06, PC-06 | F7: Stop 6 of the demo run-sheet (doc 12) | G7: T6a, T6c | H7: Added by the implementer
A8: X-07 | B8: Safeguard | C8: A BRM cannot be certified unless its four checks are ticked | D8: Certification means quantity, rate, inspection and delivery were actually checked against the PO. | E8: P-08, PC-06, A-03 | F8: Any certified BRM on DEV, e.g. BRM-2026-00003 | G8: T6n | H8: Added by the implementer
A9: X-08 | B9: Safeguard | C9: Kick-off held until the customer PO matches the offer | D9: A project cannot start while the customer PO checklist is incomplete – differences in payment terms, LD, PBG are caught first. | E9: PC-01, S-04, PR-01 | F9: KICK-2026-00002 on DEV (held) | G9: T6j | H9: Added by the implementer
A10: X-09 | B10: Safeguard | C10: Two people on every purchase order | D10: Purchase sends the PO; a director approves it. One person cannot do both. | E10: P-04, PC-03 | F10: PUR-ORD-2026-00002 on DEV | G10: T6d | H10: Added by the implementer
A11: X-10 | B11: Safeguard | C11: Drawings released for manufacture only after customer approval | D11: Nothing is manufactured from a drawing the customer has not approved; only a Projects Manager releases. | E11: E-02, P-05 | F11: MSCAST Drawing Register on DEV | G11: T6d | H11: Added by the implementer
A12: X-11 | B12: Safeguard | C12: Permissions per role, and a read-only login for the CA | D12: Each person can open and do exactly what their role card says; the CA can read everything and change nothing. | E12: AC-01, AC-02 | F12: Role Cards (doc 09) | G12: T6h, T6i, T6k, T6l | H12: Added by the implementer
... A24: X-23 | B24: Documentation | C24: 13 documents | D24: Setup guide, SOPs, role cards, operating rules, cutover runbook, demo run-sheet and others, so MSCAST is not dependent on one person's memory. | E24: — | F24: ERP Plan folder; the project | G24: — | H24: Added by the implementer

Sheet Open Questions
A1: # | B1: Topic | C1: Question | D1: Related requirement IDs | E1: Who answers | F1: Needed by | G1: Answer (fill in) | H1: Status
A2: Q1 | B2: Finance Scaling Management | C2: What exactly is meant (budgets, cash-flow forecasting, multi-entity growth, credit limits)? | D2: M-02 | E2: MSCAST | F2: P0 | H2: Open
A3: Q2 | B3: PCC | C3: Share the current PCC template, who prepares/approves it, how often it is revised, and whether it is at component or assembly level. | D3: S-02, PC-03, P-09 | E3: MSCAST | F3: P0 | H3: Open
A4: Q3 | B4: Project MIS | C4: Share the 'New Project MIS' template and the monthly project cost MIS format. | D4: PC-13, A-13 | E4: MSCAST | F4: P0 | H4: Open
A5: Q4 | B5: BRM | C5: Share the Billing Routing Memo format, approvers and payment release rules. A director certifies today: confirm that is MSCAST's intent. List the suppliers to mark *Exempt from BRM certification*. | D5: P-08, A-05 | E5: MSCAST | F5: P0 | H5: Open
A6: Q5 | B6: MDM / DI / Annexure-I | C6: Share sample Material Dispatch Memo, Delivery Instruction and Annexure-I. | D6: P-11, PC-04, P-12 | E6: MSCAST | F6: P0 | H6: Open
A7: Q6 | B7: Biometric access control | C7: Device make/model and count; network; should the ERP only read punches or also control door lock/unlock? | D7: M-03 | E7: MSCAST | F7: P0 | H7: Open
A8: Q7 | B8: Daily SMS | C8: Recipients; is WhatsApp/Google Chat/email acceptable instead of SMS? Is DLT registration done? | D8: AC-05 | E8: MSCAST | F8: P0 | H8: Open
A9: Q8 | B9: Customer-owned assets | C9: What are these assets? How are they recorded today? | D9: AC-13 | E9: MSCAST | F9: P0 | H9: Open
A10: Q9 | B10: GST on closing inventory | C10: What report/working is expected? | D10: AC-18 | E10: CA | F10: P0 | H10: Open
A11: Q10 | B11: Accounting standards | C11: CA to confirm AS vs Ind AS and SMC/small-company status; is a cash flow statement needed? | D11: AC-07, A-14 | E11: CA | F11: P0 | H11: Open
A12: Q11 | B12: WIP valuation | C12: How is project WIP valued in Tally today? | D12: AC-17 | E12: CA | F12: P0 | H12: Open
A13: Q12 | B13: Payroll | C13: Headcount under PF/ESI; current payroll provider; gratuity valuation method. | D13: M-01, AC-23, AC-11 | E13: MSCAST + CA | F13: P0 | H13: Open
... A22: Q21 | B22: Self-certification on supplier bills | C22: A director can create a BRM, certify it and mark it paid, alone (build check T6g). This step releases money to an outside party. Confirm this is intended, or remove Projects Manager from the director accounts so that only Purchase can prepare a BRM. | D22: P-08, PC-06, A-05 | E22: MSCAST | F22: Before go-live | H22: Open
